Workbook

Sheet 01-Assumption
A1: NIKE INC — MODEL ASSUMPTIONS & DRIVERS
A3: Assumption | B3: FY2023A | C3: FY2024A | D3: FY2025A | E3: FY2026E | F3: FY2027E | G3: Source / Note
A4: REVENUE ASSUMPTIONS
A5: Total Revenue growth YoY | B5: - | C5: =IFERROR(('02-IS'!C11-'02-IS'!B11)/'02-IS'!B11,"-") -> 0.0028310912 | D5: =IFERROR(('02-IS'!D11-'02-IS'!C11)/'02-IS'!C11,"-") -> -0.098380125 | E5: 0.05 | F5: 0.07 | G5: Analyst consensus / mgmt guidance
A6: North America growth | E6: 0.04 | F6: 0.06
A7: EMEA growth | E7: 0.06 | F7: 0.08
A8: Asia Pacific & LatAm growth | E8: 0.07 | F8: 0.09
A9: Greater China growth | E9: 0.05 | F9: 0.08
A10: Converse growth | E10: 0.03 | F10: 0.05
A11: Global Brand Divisions growth | E11: 0.03 | F11: 0.05
A13: MARGIN ASSUMPTIONS
A14: Gross Margin % | B14: =IFERROR('02-IS'!B13/'02-IS'!B11,"-") -> 0.43524611 | C14: =IFERROR('02-IS'!C13/'02-IS'!C11,"-") -> 0.44560181 | D14: =IFERROR('02-IS'!D13/'02-IS'!D11,"-") -> 0.42734674 | E14: 0.445 | F14: 0.45 | G14: Historical avg + mgmt guidance
A15: SG&A as % of Revenue | B15: =IFERROR('02-IS'!B16/'02-IS'!B11,"-") -> 0.31975711 | C15: =IFERROR('02-IS'!C16/'02-IS'!C11,"-") -> 0.32272887 | D15: =IFERROR('02-IS'!D16/'02-IS'!D11,"-") -> 0.34740547 | E15: 0.31 | F15: 0.305 | G15: Historical trend
A16: Demand creation as % of Revenue | B16: =IFERROR('02-IS'!B14/'02-IS'!B11,"-") -> 0.079270555 | C16: =IFERROR('02-IS'!C14/'02-IS'!C11,"-") -> 0.083427437 | D16: =IFERROR('02-IS'!D14/'02-IS'!D11,"-") -> 0.10125462 | E16: 0.083 | F16: 0.082
A17: Operating overhead as % of Revenue | B17: =IFERROR('02-IS'!B15/'02-IS'!B11,"-") -> 0.24048656 | C17: =IFERROR('02-IS'!C15/'02-IS'!C11,"-") -> 0.23930143 | D17: =IFERROR('02-IS'!D15/'02-IS'!D11,"-") -> 0.24615086 | E17: 0.227 | F17: 0.223
A18: Effective Tax Rate | B18: =IFERROR('02-IS'!B23/'02-IS'!B22,"-") -> 0.18238994 | C18: =IFERROR('02-IS'!C23/'02-IS'!C22,"-") -> 0.14925373 | D18: =IFERROR('02-IS'!D23/'02-IS'!D22,"-") -> 0.17142857 | E18: 0.185 | F18: 0.185 | G18: 10-K income tax note
A20: BALANCE SHEET ASSUMPTIONS
A21: D&A as % of Revenue | B21: =IFERROR(ABS('03-CFS'!B6)/'02-IS'!B11,"-") -> 0.013725911 | C21: =IFERROR(ABS('03-CFS'!C6)/'02-IS'!C11,"-") -> 0.015497839 | D21: =IFERROR(ABS('03-CFS'!D6)/'02-IS'!D11,"-") -> 0.016735408 | E21: 0.032 | F21: 0.032 | G21: Normalization assumption (FY2023-25 actual avg ~1.5%)
A22: CapEx as % of Revenue | B22: =IFERROR(ABS('03-CFS'!B17)/'02-IS'!B11,"-") -> 0.018919499 | C22: =IFERROR(ABS('03-CFS'!C17)/'02-IS'!C11,"-") -> 0.015809353 | D22: =IFERROR(ABS('03-CFS'!D17)/'02-IS'!D11,"-") -> 0.0092854521 | E22: 0.035 | F22: 0.034 | G22: CFS / mgmt guidance
A23: Days Sales Outstanding (AR)
A24: Days Inventory Outstanding
A25: Days Payable Outstanding
A27: CAPITAL ALLOCATION
A28: Dividends paid ($mm) | B28: =IFERROR(ABS('03-CFS'!B23),"-") -> 2012 | C28: =IFERROR(ABS('03-CFS'!C23),"-") -> 2169 | D28: =IFERROR(ABS('03-CFS'!D23),"-") -> 2300 | E28: 2400 | F28: 2500
A29: Share repurchases ($mm) | B29: =IFERROR(ABS('03-CFS'!B24),"-") -> 5480 | C29: =IFERROR(ABS('03-CFS'!C24),"-") -> 4250 | D29: =IFERROR(ABS('03-CFS'!D24),"-") -> 2985 | E29: 2000 | F29: 2000
A30: Net debt repayment ($mm) | B30: =IFERROR(ABS('03-CFS'!B25),"-") -> 504 | C30: =IFERROR(ABS('03-CFS'!C25),"-") -> 0 | D30: =IFERROR(ABS('03-CFS'!D25),"-") -> 1000 | E30: 0 | F30: 500
A33: METHODOLOGY NOTES — ASSUMPTIONS
A34: Revenue growth FY2026E/2027E based on analyst consensus and Nike management guidance (May 2025 earnings call)
A35: North America: +4%/+6% — recovery from -8% FY2025 decline driven by wholesale channel normalization
A36: EMEA: +6%/+8% — resilient market, currency-neutral growth outperforming reported
A37: Greater China: +5%/+8% — gradual recovery post FY2025 headwinds, management targeting double-digit CN-neutral growth
A38: APLA: +7%/+9% — fastest growing region, emerging markets tailwind
A39: Converse: +3%/+5% — conservative assumption given structural decline in lifestyle segment
A40: Gross Margin 44.5%/45.0% — recovery toward historical 44-46% range as input costs normalize and DTC mix improve
A41: SG&A 31.0%/30.5% — operating leverage from Win Now cost reduction program ($2bn savings target)
A42: Effective Tax Rate 18.5% — consistent with Nike 3-year historical average per 10-K income tax note
A43: D&A 3.2% of revenue — based on 3-year historical average from CFS; slight increase vs FY2025 (1.7%) reflects normalization
A44: CapEx 3.5%/3.4% of revenue — management guidance range; below historical avg reflecting asset-light pivot
... A47: Net debt repayment: $0 FY2026 / $500mm FY2027 — no known senior note maturities in FY2026 per 10-K debt schedule

Sheet 02-IS
A1: NIKE INC — INCOME STATEMENT ($ in millions)
A3: Line Item | B3: FY2023A | C3: FY2024A | D3: FY2025A | E3: Margin % FY23 | F3: Margin % FY24 | G3: Margin % FY25 | H3: YoY % 23→24 | I3: YoY % 24→25 | J3: FY2026E | K3: FY2027E
A4: North America | B4: 21608 | C4: 21396 | D4: 19572 | J4: =D4*(1+'01-Assumption'!E6) -> 20354.88 | K4: =J4*(1+'01-Assumption'!F6) -> 21576.173
A5: Europe, Middle East & Africa | B5: 13418 | C5: 13607 | D5: 12257 | J5: =D5*(1+'01-Assumption'!E7) -> 12992.42 | K5: =J5*(1+'01-Assumption'!F7) -> 14031.814
A6: Asia Pacific & Latin America | B6: 6431 | C6: 6729 | D6: 6251 | J6: =D6*(1+'01-Assumption'!E8) -> 6688.57 | K6: =J6*(1+'01-Assumption'!F8) -> 7290.5413
A7: Greater China | B7: 7248 | C7: 7545 | D7: 6586 | J7: =D7*(1+'01-Assumption'!E9) -> 6915.3 | K7: =J7*(1+'01-Assumption'!F9) -> 7468.524
A8: Converse | B8: 2427 | C8: 2082 | D8: 1692 | J8: =D8*(1+'01-Assumption'!E10) -> 1742.76 | K8: =J8*(1+'01-Assumption'!F10) -> 1829.898
A9: Coporate | B9: 27 | C9: -42 | D9: -97 | J9: =D9*(1+'01-Assumption'!E5) -> -101.85 | K9: =J9*(1+'01-Assumption'!F5) -> -108.9795
A10: Global Brand Divisions | B10: 58 | C10: 45 | D10: 48 | J10: =D10 -> 48 | K10: =D10 -> 48
A11: TOTAL REVENUES | B11: =SUM(B4:B10) -> 51217 | C11: =SUM(C4:C10) -> 51362 | D11: =SUM(D4:D10) -> 46309 | E11: =IFERROR(B11/B11,"-") -> 1 | F11: =IFERROR(C11/C11,"-") -> 1 | G11: =IFERROR(D11/D11,"-") -> 1 | H11: =IFERROR((C11-B11)/B11,"-") -> 0.0028310912 | I11: =IFERROR((D11-C11)/C11,"-") -> -0.098380125 | J11: =D11*(1+'01-Assumption'!E5) -> 48624.45 | K11: =J11*(1+'01-Assumption'!F5) -> 52028.162
A12: Cost of Sales | B12: 28925 | C12: 28475 | D12: 26519 | J12: =J11*(1-'01-Assumption'!E14) -> 26986.57 | K12: =K11*(1-'01-Assumption'!F14) -> 28615.489
A13: GROSS PROFIT | B13: =B11-B12 -> 22292 | C13: =C11-C12 -> 22887 | D13: =D11-D12 -> 19790 | E13: =IFERROR(B13/B11,"-") -> 0.43524611 | F13: =IFERROR(C13/C11,"-") -> 0.44560181 | G13: =IFERROR(D13/D11,"-") -> 0.42734674 | H13: =IFERROR((C13-B13)/B13,"-") -> 0.02669119 | I13: =IFERROR((D13-C13)/C13,"-") -> -0.13531699 | J13: =J11-J12 -> 21637.88 | K13: =K11-K12 -> 23412.673
A14: Demand creation expense | B14: 4060 | C14: 4285 | D14: 4689 | J14: =J11*'01-Assumption'!E16 -> 4035.8293 | K14: =K11*'01-Assumption'!F16 -> 4266.3092
A15: Operating overhead expense | B15: 12317 | C15: 12291 | D15: 11399 | J15: =J11*'01-Assumption'!E17 -> 11037.75 | K15: =K11*'01-Assumption'!F17 -> 11602.28
A16: TOTAL SG&A | B16: =B14+B15 -> 16377 | C16: =C14+C15 -> 16576 | D16: =D14+D15 -> 16088 | J16: =J14+J15 -> 15073.579 | K16: =K14+K15 -> 15868.589
A17: EBIT | B17: =B13-B16 -> 5915 | C17: =C13-C16 -> 6311 | D17: =D13-D16 -> 3702 | E17: =IFERROR(B17/B11,"-") -> 0.115489 | F17: =IFERROR(C17/C11,"-") -> 0.12287294 | G17: =IFERROR(D17/D11,"-") -> 0.079941264 | H17: =IFERROR((C17-B17)/B17,"-") -> 0.066948436 | I17: =IFERROR((D17-C17)/C17,"-") -> -0.41340517 | J17: =J13-J16 -> 6564.3008 | K17: =K13-K16 -> 7544.0834
A18: D&A (add-back) | B18: 703 | C18: 796 | D18: 775 | J18: =J11*'01-Assumption'!E21 -> 1555.9824 | K18: =K11*'01-Assumption'!F21 -> 1664.9012
A19: EBITDA | B19: =B17+B18 -> 6618 | C19: =C17+C18 -> 7107 | D19: =D17+D18 -> 4477 | E19: =IFERROR(B19/B11,"-") -> 0.12921491 | F19: =IFERROR(C19/C11,"-") -> 0.13837078 | G19: =IFERROR(D19/D11,"-") -> 0.096676672 | H19: =IFERROR((C19-B19)/B19,"-") -> 0.073889393 | I19: =IFERROR((D19-C19)/C19,"-") -> -0.37005769 | J19: =J17+J18 -> 8120.2832 | K19: =K17+K18 -> 9208.9846
A20: Interest expense, net | B20: -6 | C20: -161 | D20: -107 | J20: =D20 -> -107 | K20: =D20 -> -107
A21: Other income (expense), net | B21: 280 | C21: 228 | D21: 76 | J21: =D21 -> 76 | K21: =D21 -> 76
A22: EBT | B22: =B17-B20+B21 -> 6201 | C22: =C17-C20+C21 -> 6700 | D22: =D17-D20+D21 -> 3885 | J22: =J17+J20+J21 -> 6533.3008 | K22: =K17+K20+K21 -> 7513.0834
A23: Income tax expense | B23: 1131 | C23: 1000 | D23: 666 | J23: =J22*'01-Assumption'!E18 -> 1208.6606 | K23: =K22*'01-Assumption'!F18 -> 1389.9204
A24: NET INCOME | B24: =B22-B23 -> 5070 | C24: =C22-C23 -> 5700 | D24: =D22-D23 -> 3219 | E24: =IFERROR(B24/B11,"-") -> 0.09899057 | F24: =IFERROR(C24/C11,"-") -> 0.11097699 | G24: =IFERROR(D24/D11,"-") -> 0.069511326 | H24: =IFERROR((C24-B24)/B24,"-") -> 0.12426036 | I24: =IFERROR((D24-C24)/C24,"-") -> -0.43526316 | J24: =J22-J23 -> 5324.6401 | K24: =K22-K23 -> 6123.163
A28: METHODOLOGY NOTES — INCOME STATEMEN
A29: Source: Nike Inc. 10-K FY2023 (filed July 2023), FY2024 (filed July 2024), FY2025 (filed July 2025) — SEC EDGAR (sec.gov)
A30: Revenue segments: North America, EMEA, Greater China, APLA, Converse, Corporate per Note 15 Segment Information
A31: Corporate revenue: unallocated licensing and other miscellaneous revenues immaterial, kept stable in projections
A32: D&A add-back (line 18): sourced from CFS Supplemental Disclosure, not separately reported on face of IS
A33: Interest expense net: Nike reported net interest income in FY2023-2025 due to cash position exceeding debt, entered as negative
A34: Other income (expense) net: includes FX gains/losses and non-operating items, kept at FY2025 level in projections (conservative)
A35: Projected revenues FY2026E/2027E: linked from 01-Assumption, change assumptions there to update all projections
A36: Projected margins: Cost of Sales derived from (1 - Gross Margin %) × Revenue; SG&A from Demand creation % + Operating overhead % of Revenue
A37: All figures in USD millions unless otherwise noted
A38: Nike fiscal year ends May 31 — FY2025 = June 2024 to May 2025

Sheet 03-CFS
A1: NIKE INC — CASH FLOW STATEMENT ($ in millions)
A3: Line Item | B3: FY2023A | C3: FY2024A | D3: FY2025A | E3: FY2026E | F3: FY2027E | H3: YoY % 23→24 | I3: YoY % 24→25
A4: OPERATING ACTIVITIES
A5: Net Income | B5: ='02-IS'!B24 -> 5070 | C5: ='02-IS'!C24 -> 5700 | D5: ='02-IS'!D24 -> 3219 | E5: ='02-IS'!J24 -> 5324.6401 | F5: ='02-IS'!K24 -> 6123.163
A6: Depreciation & Amortization | B6: 703 | C6: 796 | D6: 775 | E6: ='02-IS'!J11*'01-Assumption'!E21 -> 1555.9824 | F6: ='02-IS'!K11*'01-Assumption'!F21 -> 1664.9012
A7: Stock-based compensation | B7: 755 | C7: 804 | D7: 709 | E7: =D7 -> 709 | F7: =E7 -> 709
A8: Deferred income taxes | B8: -117 | C8: -497 | D8: -288 | E8: =D8 -> -288 | F8: =E8 -> -288
A9: (Increase)/decrease in Accounts Receivable | B9: 489 | C9: -329 | D9: -257 | E9: =D9 -> -257 | F9: =E9 -> -257
A10: (Increase)/decrease in Inventories | B10: -133 | C10: 908 | D10: 120 | E10: =D10 -> 120 | F10: =E10 -> 120
A11: Increase/(decrease) in Accounts Payable | B11: -225 | C11: 397 | D11: -426 | E11: =D11 -> -426 | F11: =E11 -> -426
A12: Change in prepaid and others | B12: -644 | C12: -260 | D12: -224 | E12: =D12 -> -224 | F12: =E12 -> -224
A13: Other working capital changes | B13: -57 | C13: -90 | D13: 70 | E13: =D13 -> 70 | F13: =E13 -> 70
A14: OPERATING CASH FLOW | B14: =SUM(B5:B13) -> 5841 | C14: =SUM(C5:C13) -> 7429 | D14: =SUM(D5:D13) -> 3698 | E14: =SUM(E5:E13) -> 6584.6225 | F14: =SUM(F5:F13) -> 7492.0642 | H14: =IFERROR((C14-B14)/ABS(B14),"-") -> 0.27187125 | I14: =IFERROR((D14-C14)/ABS(C14),"-") -> -0.50222103
A16: INVESTING ACTIVITIES
A17: Capital expenditures (CapEx) | B17: -969 | C17: -812 | D17: -430 | E17: =-'02-IS'!J11*'01-Assumption'!E22 -> -1701.8557 | F17: =-'02-IS'!K11*'01-Assumption'!F22 -> -1768.9575
A18: Acquisitions & investments, net | B18: 1481 | C18: 1721 | D18: 147 | E18: =D18 -> 147 | F18: =E18 -> 147
A19: Other investing activities | B19: 52 | C19: -15 | D19: 8 | E19: =D19 -> 8 | F19: =E19 -> 8
A20: INVESTING CASH FLOW | B20: =SUM(B17:B19) -> 564 | C20: =SUM(C17:C19) -> 894 | D20: =SUM(D17:D19) -> -275 | E20: =SUM(E17:E19) -> -1546.8557 | F20: =SUM(F17:F19) -> -1613.9575 | H20: =IFERROR((C20-B20)/ABS(B20),"-") -> 0.58510638 | I20: =IFERROR((D20-C20)/ABS(C20),"-") -> -1.3076063
A22: FINANCING ACTIVITIES
A23: Dividends paid | B23: -2012 | C23: -2169 | D23: -2300 | E23: =-'01-Assumption'!E28 -> -2400 | F23: =-'01-Assumption'!F28 -> -2500
A24: Share repurchases | B24: -5480 | C24: -4250 | D24: -2985 | E24: =-'01-Assumption'!E29 -> -2000 | F24: =-'01-Assumption'!F29 -> -2000
A25: Net borrowings / (repayments) | B25: -504 | C25: 0 | D25: -1000 | E25: =-'01-Assumption'!E30 -> 0 | F25: =-'01-Assumption'!F30 -> -500
A26: Other financing activities | B26: 549 | C26: 531 | D26: 466 | E26: =D26 -> 466 | F26: =E26 -> 466
A27: FINANCING CASH FLOW | B27: =SUM(B23:B26) -> -7447 | C27: =SUM(C23:C26) -> -5888 | D27: =SUM(D23:D26) -> -5819 | E27: =SUM(E23:E26) -> -3934 | F27: =SUM(F23:F26) -> -4534 | H27: =IFERROR((C27-B27)/ABS(B27),"-") -> 0.20934605 | I27: =IFERROR((D27-C27)/ABS(C27),"-") -> 0.01171875
A29: Net change in cash | B29: =B14+B20+B27 -> -1042 | C29: =C14+C20+C27 -> 2435 | D29: =D14+D20+D27 -> -2396 | E29: =E14+E20+E27 -> 1103.7668 | F29: =F14+F20+F27 -> 1344.1067
A30: Effect of exchange rates | B30: -91 | C30: -16 | D30: 1 | E30: =D30 -> 1 | F30: =E30 -> 1
A31: Beginning cash balance | B31: 8574 | C31: 7441 | D31: 9860 | E31: =D32 -> 7465 | F31: =E32 -> 8569.7668
A32: ENDING CASH BALANCE | B32: =B29+B31+B30 -> 7441 | C32: =C29+C31+C30 -> 9860 | D32: =D29+D31+D30 -> 7465 | E32: =E29+E31+E30 -> 8569.7668 | F32: =F29+F31+F30 -> 9914.8734
A34: FREE CASH FLOW (OCF - CapEx) | B34: =B14+B17 -> 4872 | C34: =C14+C17 -> 6617 | D34: =D14+D17 -> 3268 | E34: =E14+E17 -> 4882.7668 | F34: =F14+F17 -> 5723.1067 | H34: =IFERROR((C34-B34)/ABS(B34),"-") -> 0.35816913 | I34: =IFERROR((D34-C34)/ABS(C34),"-") -> -0.5061206
A38: METHODOLOGY NOTES — CASH FLOW STATEMENT
A39: Source: Nike Inc. 10-K FY2023, FY2024, FY2025 — Consolidated Statements of Cash Flows
A40: Net Income: auto-linked from 02-IS — any change in IS projections flows through automatically
A41: D&A: sourced from CFS Supplemental Disclosure table (FY2024 10-K Note segment table)
A42: Short-term investments: grouped into "Acquisitions & investments, net" — net of purchases, maturities and sales
A43: Effect of exchange rates on cash: historical actuals kept at FY2025 level (1mm) for projections — immaterial
A44: Working capital changes FY2026E/2027E: kept at FY2025 levels by conservatism — no DSO/DIO/DPO model built at this stage
A45: CapEx FY2026E/2027E: linked from 01-Assumption (3.5%/3.4% of projected revenue) — entered as negative per convention
A46: Dividends and buybacks: linked from 01-Assumption Capital Allocation section
A47: Other financing activities: includes proceeds from stock option exercises (~$466mm/year) — kept stable at FY2025 level
A48: FCF defined as Operating Cash Flow + CapEx (CapEx negative by convention)
...

Sheet 04-BS
A1: NIKE INC — BALANCE SHEET ($ in millions)
A3: Line Item | B3: FY2023A | C3: FY2024A | D3: FY2025A | E3: FY2026E | F3: FY2027E | H3: YoY % 23→24 | I3: YoY % 24→25
A4: ASSETS
A5: Current Assets
A6: Cash & equivalents | B6: 7441 | C6: 9860 | D6: 7464 | E6: ='03-CFS'!E32 -> 8569.7668 | F6: ='03-CFS'!F32 -> 9914.8734
A7: Short term investments | B7: 3234 | C7: 1722 | D7: 1687 | E7: =D7 -> 1687 | F7: =E7 -> 1687
A8: Accounts receivable, net | B8: 4131 | C8: 4427 | D8: 4717 | E8: =D8 -> 4717 | F8: =E8 -> 4717
A9: Inventories | B9: 8454 | C9: 7519 | D9: 7489 | E9: =D9 -> 7489 | F9: =E9 -> 7489
A10: Prepaid expenses & other current assets | B10: 1942 | C10: 1854 | D10: 2005 | E10: =D10 -> 2005 | F10: =E10 -> 2005
A11: TOTAL CURRENT ASSETS | B11: =SUM(B6:B10) -> 25202 | C11: =SUM(C6:C10) -> 25382 | D11: =SUM(D6:D10) -> 23362 | E11: =SUM(E6:E10) -> 24467.767 | F11: =SUM(F6:F10) -> 25812.873
A13: Non-Current Assets
A14: Property, plant & equipment, net | B14: 5081 | C14: 5000 | D14: 4828 | E14: =D14 -> 4828 | F14: =E14 -> 4828
A15: Operating lease right-of-use assets | B15: 2923 | C15: 2718 | D15: 2712 | E15: =D15 -> 2712 | F15: =E15 -> 2712
A16: Intangible assets & goodwill, net | B16: 555 | C16: 499 | D16: 499 | E16: =D16 -> 499 | F16: =E16 -> 499
A17: Deferred income taxes & other | B17: 3770 | C17: 4511 | D17: 5178 | E17: =D17 -> 5178 | F17: =E17 -> 5178
A18: TOTAL NON-CURRENT ASSETS | B18: =SUM(B14:B17) -> 12329 | C18: =SUM(C14:C17) -> 12728 | D18: =SUM(D14:D17) -> 13217 | E18: =SUM(E14:E17) -> 13217 | F18: =SUM(F14:F17) -> 13217
A19: TOTAL ASSETS | B19: =B11+B18 -> 37531 | C19: =C11+C18 -> 38110 | D19: =D11+D18 -> 36579 | E19: =E11+E18 -> 37684.767 | F19: =F11+F18 -> 39029.873 | H19: =IFERROR((C19-B19)/B19,"-") -> 0.015427247 | I19: =IFERROR((D19-C19)/C19,"-") -> -0.040173183
A21: LIABILITIES & EQUITY
A22: Current Liabilities
A23: Accounts payable | B23: 2862 | C23: 2851 | D23: 3479 | E23: =D23 -> 3479 | F23: =E23 -> 3479
A24: Note payable | B24: 6 | C24: 6 | D24: 5 | E24: =D24 -> 5 | F24: =E24 -> 5
A25: Income Taxes payable | B25: 240 | C25: 534 | D25: 669 | E25: =D25 -> 669 | F25: =E25 -> 669
A26: Accrued liabilities | B26: 5723 | C26: 5725 | D26: 5911 | E26: =D26 -> 5911 | F26: =E26 -> 5911
A27: Current portion of long-term debt | B27: 0 | C27: 1000 | D27: 0 | E27: =D27 -> 0 | F27: =E27 -> 0
A28: Current operating lease liabilities | B28: 425 | C28: 477 | D28: 502 | E28: =D28 -> 502 | F28: =E28 -> 502
A29: TOTAL CURRENT LIABILITIES | B29: =SUM(B23:B28) -> 9256 | C29: =SUM(C23:C28) -> 10593 | D29: =SUM(D23:D28) -> 10566 | E29: =SUM(E23:E28) -> 10566 | F29: =SUM(F23:F28) -> 10566 | H29: =IFERROR((C29-B29)/B29,"-") -> 0.14444685 | I29: =IFERROR((D29-C29)/C29,"-") -> -0.002548853
A31: Non-Current Liabilities
A32: Long-term debt | B32: 8927 | C32: 7903 | D32: 7961 | E32: =D32+'03-CFS'!E25 -> 7961 | F32: =E32+'03-CFS'!F25 -> 7461
A33: Non-current operating lease liabilities | B33: 2786 | C33: 2566 | D33: 2550 | E33: =D33 -> 2550 | F33: =E33 -> 2550
A34: Deferred income taxes & other liabilities | B34: 2558 | C34: 2618 | D34: 2289 | E34: =D34 -> 2289 | F34: =E34 -> 2289
A35: TOTAL NON-CURRENT LIABILITIES | B35: =SUM(B32:B34) -> 14271 | C35: =SUM(C32:C34) -> 13087 | D35: =SUM(D32:D34) -> 12800 | E35: =SUM(E32:E34) -> 12800 | F35: =SUM(F32:F34) -> 12300
A36: TOTAL LIABILITIES | B36: =B29+B35 -> 23527 | C36: =C29+C35 -> 23680 | D36: =D29+D35 -> 23366 | E36: =E29+E35 -> 23366 | F36: =F29+F35 -> 22866 | H36: =IFERROR((C36-B36)/B36,"-") -> 0.0065031666 | I36: =IFERROR((D36-C36)/C36,"-") -> -0.013260135
A38: Shareholders' Equity
A39: Common stock & additional paid-in capital | B39: 12415 | C39: 13412 | D39: 14198 | E39: =D39 -> 14198 | F39: =E39 -> 14198
A40: Retained earnings (accumulated deficit) | B40: 1358 | C40: 965 | D40: -727 | E40: =D40+'02-IS'!J24+'03-CFS'!E23+'03-CFS'!E24 -> 197.64011 | F40: =E40+'02-IS'!K24+'03-CFS'!F23+'03-CFS'!F24 -> 1820.8031
A41: Accumulated other comprehensive loss | B41: 231 | C41: 53 | D41: -258 | E41: =D41 -> -258 | F41: =E41 -> -258
A42: TOTAL SHAREHOLDERS' EQUITY | B42: =SUM(B39:B41) -> 14004 | C42: =SUM(C39:C41) -> 14430 | D42: =SUM(D39:D41) -> 13213 | E42: =SUM(E39:E41) -> 14137.64 | F42: =SUM(F39:F41) -> 15760.803 | H42: =IFERROR((C42-B42)/B42,"-") -> 0.03041988 | I42: =IFERROR((D42-C42)/C42,"-") -> -0.084338184
A43: TOTAL LIABILITIES & EQUITY | B43: =B36+B42 -> 37531 | C43: =C36+C42 -> 38110 | D43: =D36+D42 -> 36579 | E43: =E36+E42 -> 37503.64 | F43: =F36+F42 -> 38626.803 | H43: =IFERROR((C43-B43)/B43,"-") -> 0.015427247 | I43: =IFERROR((D43-C43)/C43,"-") -> -0.040173183
A45: BALANCE SHEET CHECK (must = 0) | B45: =B19-B43 -> 0 | C45: =C19-C43 -> 0 | D45: =D19-D43 -> 0 | E45: =E19-E43 -> 181.12665 | F45: =F19-F43 -> 403.07033
A48: METHODOLOGY NOTES — BALANCE SHEET
...

Sheet 05-DASH
A1: NIKE INC — KPI DASHBOARD
A3: KPI | B3: FY2023A | C3: FY2024A | D3: FY2025A | E3: YoY % 23→24 | F3: YoY % 24→25 | G3: Benchmark
A4: PROFITABILITY
A5: ① Net Profit Margin | B5: =IFERROR('02-IS'!B24/'02-IS'!B11,"-") -> 0.09899057 | C5: =IFERROR('02-IS'!C24/'02-IS'!C11,"-") -> 0.11097699 | D5: =IFERROR('02-IS'!D24/'02-IS'!D11,"-") -> 0.069511326 | E5: =IFERROR((C5-B5)/ABS(B5),"-") -> 0.12108646 | F5: =IFERROR((D5-C5)/ABS(C5),"-") -> -0.37364198 | G5: 10-14% target
A6: ② Gross Margin % | B6: =IFERROR('02-IS'!B13/'02-IS'!B11,"-") -> 0.43524611 | C6: =IFERROR('02-IS'!C13/'02-IS'!C11,"-") -> 0.44560181 | D6: =IFERROR('02-IS'!D13/'02-IS'!D11,"-") -> 0.42734674 | E6: =IFERROR((C6-B6)/ABS(B6),"-") -> 0.023792739 | F6: =IFERROR((D6-C6)/ABS(C6),"-") -> -0.040967228 | G6: 44-46% target
A7: ③ EBITDA Margin % | B7: =IFERROR('02-IS'!B19/'02-IS'!B11,"-") -> 0.12921491 | C7: =IFERROR('02-IS'!C19/'02-IS'!C11,"-") -> 0.13837078 | D7: =IFERROR('02-IS'!D19/'02-IS'!D11,"-") -> 0.096676672 | E7: =IFERROR((C7-B7)/ABS(B7),"-") -> 0.070857697 | F7: =IFERROR((D7-C7)/ABS(C7),"-") -> -0.30132162 | G7: 15-17% target
A8: ④ Revenue Growth YoY | B8: - | C8: =IFERROR(('02-IS'!C11-'02-IS'!B11)/'02-IS'!B11,"-") -> 0.0028310912 | D8: =IFERROR(('02-IS'!D11-'02-IS'!C11)/'02-IS'!C11,"-") -> -0.098380125 | G8: 5-8% target
A10: RETURNS & LEVERAGE
A11: ⑤ Return on Equity (ROE) | B11: =IFERROR('02-IS'!B24/'04-BS'!B42,"-") -> 0.36203942 | C11: =IFERROR('02-IS'!C24/'04-BS'!C42,"-") -> 0.3950104 | D11: =IFERROR('02-IS'!D24/'04-BS'!D42,"-") -> 0.2436237 | E11: =IFERROR((C11-B11)/ABS(B11),"-") -> 0.091070132 | F11: =IFERROR((D11-C11)/ABS(C11),"-") -> -0.38324736 | G11: 30-50% (buybacks)
A12: ⑥ Debt / EBITDA | B12: =IFERROR('04-BS'!B32/'02-IS'!B19,"-") -> 1.3488969 | C12: =IFERROR('04-BS'!C32/'02-IS'!C19,"-") -> 1.1120023 | D12: =IFERROR('04-BS'!D32/'02-IS'!D19,"-") -> 1.7781997 | E12: =IFERROR((C12-B12)/ABS(B12),"-") -> -0.17562105 | F12: =IFERROR((D12-C12)/ABS(C12),"-") -> 0.5990972 | G12: < 2.0x
A13: ⑦ Current Ratio | B13: =IFERROR('04-BS'!B11/'04-BS'!B29,"-") -> 2.7227744 | C13: =IFERROR('04-BS'!C11/'04-BS'!C29,"-") -> 2.3961106 | D13: =IFERROR('04-BS'!D11/'04-BS'!D29,"-") -> 2.2110543 | E13: =IFERROR((C13-B13)/ABS(B13),"-") -> -0.1199746 | F13: =IFERROR((D13-C13)/ABS(C13),"-") -> -0.077231957 | G13: > 1.5x
A15: CASH FLOW
A16: ⑧ Free Cash Flow ($mm) | B16: ='03-CFS'!B34 -> 4872 | C16: ='03-CFS'!C34 -> 6617 | D16: ='03-CFS'!D34 -> 3268 | E16: =IFERROR((C16-B16)/ABS(B16),"-") -> 0.35816913 | F16: =IFERROR((D16-C16)/ABS(C16),"-") -> -0.5061206 | G16: $4-6bn target
A17: ⑨ FCF Margin % | B17: =IFERROR('03-CFS'!B34/'02-IS'!B11,"-") -> 0.095124666 | C17: =IFERROR('03-CFS'!C34/'02-IS'!C11,"-") -> 0.12883065 | D17: =IFERROR('03-CFS'!D34/'02-IS'!D11,"-") -> 0.070569436 | E17: =IFERROR((C17-B17)/ABS(B17),"-") -> 0.35433488 | F17: =IFERROR((D17-C17)/ABS(C17),"-") -> -0.45223102 | G17: 8-12% target
A18: ⑩ CapEx as % of Revenue | B18: =IFERROR('03-CFS'!B17/'02-IS'!B11,"-") -> -0.018919499 | C18: =IFERROR('03-CFS'!C17/'02-IS'!C11,"-") -> -0.015809353 | D18: =IFERROR('03-CFS'!D17/'02-IS'!D11,"-") -> -0.0092854521 | E18: =IFERROR((C18-B18)/ABS(B18),"-") -> 0.1643884 | F18: =IFERROR((D18-C18)/ABS(C18),"-") -> 0.41266085 | G18: 3-4% typical (negatif)
A22: Segment | B22: FY2023A | C22: FY2024A | D22: FY2025A
A23: North America | B23: ='02-IS'!B4 -> 21608 | C23: ='02-IS'!C4 -> 21396 | D23: ='02-IS'!D4 -> 19572
A24: EMEA | B24: ='02-IS'!B5 -> 13418 | C24: ='02-IS'!C5 -> 13607 | D24: ='02-IS'!D5 -> 12257
A25: APLA | B25: ='02-IS'!B6 -> 6431 | C25: ='02-IS'!C6 -> 6729 | D25: ='02-IS'!D6 -> 6251
A26: Greater China | B26: ='02-IS'!B7 -> 7248 | C26: ='02-IS'!C7 -> 7545 | D26: ='02-IS'!D7 -> 6586
A27: Converse | B27: ='02-IS'!B8 -> 2427 | C27: ='02-IS'!C8 -> 2082 | D27: ='02-IS'!D8 -> 1692
A30: Metric | B30: FY2023A | C30: FY2024A | D30: FY2025A
A31: Gross Margin % | B31: ='05-DASH'!B6 -> 0.43524611 | C31: ='05-DASH'!C6 -> 0.44560181 | D31: ='05-DASH'!D6 -> 0.42734674
A32: EBITDA Margin % | B32: ='05-DASH'!B7 -> 0.12921491 | C32: ='05-DASH'!C7 -> 0.13837078 | D32: ='05-DASH'!D7 -> 0.096676672
A33: Net Margin % | B33: ='05-DASH'!B5 -> 0.09899057 | C33: ='05-DASH'!C5 -> 0.11097699 | D33: ='05-DASH'!D5 -> 0.069511326
A36: Metric | B36: FY2023A | C36: FY2024A | D36: FY2025A
A37: Free Cash Flow | B37: ='05-DASH'!B16 -> 4872 | C37: ='05-DASH'!C16 -> 6617 | D37: ='05-DASH'!D16 -> 3268
A38: CapEx | B38: ='03-CFS'!B17 -> -969 | C38: ='03-CFS'!C17 -> -812 | D38: ='03-CFS'!D17 -> -430
A41: KPI | B41: FY2023A | C41: FY2024A | D41: FY2025A
A42: ROE % | B42: ='05-DASH'!B11 -> 0.36203942 | C42: ='05-DASH'!C11 -> 0.3950104 | D42: ='05-DASH'!D11 -> 0.2436237
A43: Current Ratio | B43: ='05-DASH'!B13 -> 2.7227744 | C43: ='05-DASH'!C13 -> 2.3961106 | D43: ='05-DASH'!D13 -> 2.2110543
A44: Debt/EBITDA | B44: ='05-DASH'!B12 -> 1.3488969 | C44: ='05-DASH'!C12 -> 1.1120023 | D44: ='05-DASH'!D12 -> 1.7781997
A45: Chart : Current Ratio et Debt/EBITDA en multiple (x), ROE en %
A48: Metric | B48: FY2023A | C48: FY2024A | D48: FY2025A | E48: FY2026E | F48: FY2027E
A49: Net Income ($mm) | B49: ='02-IS'!B24 -> 5070 | C49: ='02-IS'!C24 -> 5700 | D49: ='02-IS'!D24 -> 3219 | E49: ='02-IS'!J24 -> 5324.6401 | F49: ='02-IS'!K24 -> 6123.163
A52: METHODOLOGY NOTES — KPI DASHBOARD
A53: All KPIs auto-linked from 02-IS, 03-CFS, 04-BS — update source data to refresh dashboard automatically
A54: Net Profit Margin = Net Income / Total Revenues
A55: Gross Margin % = Gross Profit / Total Revenues
A56: EBITDA Margin % = EBITDA / Total Revenues — EBITDA not reported by Nike; calculated as EBIT + D&A add-back
...

Sheet 06-DCF
A1: NIKE INC — DCF VALUATION ($ in millions)
A3: Line Item | B3: FY2023A | C3: FY2024A | D3: FY2025A | E3: FY2026E | F3: FY2027E | G3: FY2028E | H3: FY2029E | I3: FY2030E
A5: REVENUE PROJECTIONS
A6: Total Revenue | B6: ='02-IS'!B11 -> 51217 | C6: ='02-IS'!C11 -> 51362 | D6: ='02-IS'!D11 -> 46309 | E6: ='02-IS'!J11 -> 48624.45 | F6: ='02-IS'!K11 -> 52028.162 | G6: =F6*(1+G7) -> 55149.851 | H6: =G6*(1+H7) -> 57907.344 | I6: =H6*(1+I7) -> 60223.637
A7: Revenue growth % | E7: ='01-Assumption'!E5 -> 0.05 | F7: ='01-Assumption'!F5 -> 0.07 | G7: 0.06 | H7: 0.05 | I7: 0.04
A9: PROFITABILITY
A10: Gross Margin % | E10: ='01-Assumption'!E14 -> 0.445 | F10: ='01-Assumption'!F14 -> 0.45 | G10: 0.455 | H10: 0.46 | I10: 0.46
A11: EBIT margin % | B11: ='02-IS'!B17/'02-IS'!B11 -> 0.115489 | C11: ='02-IS'!C17/'02-IS'!C11 -> 0.12287294 | D11: ='02-IS'!D17/'02-IS'!D11 -> 0.079941264 | E11: ='02-IS'!J17/'02-IS'!J11 -> 0.135 | F11: ='02-IS'!K17/'02-IS'!K11 -> 0.145 | G11: 0.135 | H11: 0.14 | I11: 0.14
A12: EBIT | B12: ='02-IS'!B17 -> 5915 | C12: ='02-IS'!C17 -> 6311 | D12: ='02-IS'!D17 -> 3702 | E12: ='02-IS'!J17 -> 6564.3008 | F12: ='02-IS'!K17 -> 7544.0834 | G12: =G6*G11 -> 7445.2299 | H12: =H6*H11 -> 8107.0281 | I12: =I6*I11 -> 8431.3092
A13: Tax rate | E13: ='01-Assumption'!E18 -> 0.185 | F13: ='01-Assumption'!F18 -> 0.185 | G13: =F13 -> 0.185 | H13: =G13 -> 0.185 | I13: =H13 -> 0.185
A14: NOPAT | B14: =B12*(1-E13) -> 4820.725 | C14: =C12*(1-E13) -> 5143.465 | D14: =D12*(1-E13) -> 3017.13 | E14: =E12*(1-E13) -> 5349.9051 | F14: =F12*(1-F13) -> 6148.428 | G14: =G12*(1-G13) -> 6067.8624 | H14: =H12*(1-H13) -> 6607.2279 | I14: =I12*(1-I13) -> 6871.517
A16: D&A | B16: ='02-IS'!B18 -> 703 | C16: ='02-IS'!C18 -> 796 | D16: ='02-IS'!D18 -> 775 | E16: ='02-IS'!J18 -> 1555.9824 | F16: ='02-IS'!K18 -> 1664.9012 | G16: =G6*3.2% -> 1764.7952 | H16: =H6*3.2% -> 1853.035 | I16: =I6*3.2% -> 1927.1564
A17: Capex | B17: ='03-CFS'!B17 -> -969 | C17: ='03-CFS'!C17 -> -812 | D17: ='03-CFS'!D17 -> -430 | E17: ='03-CFS'!E17 -> -1701.8557 | F17: ='03-CFS'!F17 -> -1768.9575 | G17: =G6*3.3%*-1 -> -1819.9451 | H17: =H6*3.2%*-1 -> -1853.035 | I17: =I6*3.1%*-1 -> -1866.9328
A18: NWC (CA - CL) | B18: ='04-BS'!B11-'04-BS'!B29 -> 15946 | C18: ='04-BS'!C11-'04-BS'!C29 -> 14789 | D18: ='04-BS'!D11-'04-BS'!D29 -> 12796 | E18: =E6*18% -> 8752.401 | F18: =F6*18% -> 9365.0691 | G18: =G6*18% -> 9926.9732 | H18: =H6*18% -> 10423.322 | I18: =I6*18% -> 10840.255
A19: ΔNWC (variation) | B19: =B18-C18 -> 1157 | C19: =C18-B18 -> -1157 | D19: =D18-C18 -> -1993 | E19: =E18-D18 -> -4043.599 | F19: =F18-E18 -> 612.66807 | G19: =G18-F18 -> 561.90414 | H19: =H18-G18 -> 496.34866 | I19: =I18-H18 -> 416.93287
A21: FREE CASH FLOW TO FIRM (FCFF)
A22: FCFF | E22: =E14+E16+E17-E19 -> 9247.6308 | F22: =F14+F16+F17-F19 -> 5431.7036 | G22: =G14+G16+G17-G19 -> 5450.8084 | H22: =H14+H16+H17-H19 -> 6110.8793 | I22: =I14+I16+I17-I19 -> 6514.8078
A23: FCFF margin % | E23: =E22/E6 -> 0.19018479 | F23: =F22/F6 -> 0.1043993 | G23: =G22/G6 -> 0.098836321 | H23: =H22/H6 -> 0.10552857 | I23: =I22/I6 -> 0.10817692
A25: DCF VALUATION
A26: WACC | E26: ='07-WACC'!B25 -> 0.10755602 | F26: =E26 -> 0.10755602 | G26: =F26 -> 0.10755602 | H26: =G26 -> 0.10755602 | I26: =H26 -> 0.10755602
A27: Discount period | E27: 1 | F27: 2 | G27: 3 | H27: 4 | I27: 5
A28: Discount factor | E28: =1/(1+E26)^E27 -> 0.90288886 | F28: =1/(1+F26)^F27 -> 0.8152083 | G28: =1/(1+G26)^G27 -> 0.7360425 | H28: =1/(1+H26)^H27 -> 0.66456457 | I28: =1/(1+I26)^I27 -> 0.60002795
A29: PV of FCFF | E29: =E22*E28 -> 8349.5828 | F29: =F22*F28 -> 4427.9699 | G29: =G22*G28 -> 4012.0266 | H29: =H22*H28 -> 4061.0739 | I29: =I22*I28 -> 3909.0668
A30: Sum of PV (FCFF) | E30: =SUM(E29:I29) -> 24759.72
A32: TERMINAL VALUE
A33: Terminal growth rate (g) | E33: 0.025
A34: Terminal Value (Gordon Growth) | E34: =I22*(1+E33)/(E26-E33) -> 80886.623
A35: PV of Terminal Value | E35: =E34*I28 -> 48534.235
A36: TV as % of Total Value | E36: =E35/(E30+E35) -> 0.66218606
A38: EQUITY VALUE BRIDGE
A39: Enterprise Value (EV) | E39: =E30+E35 -> 73293.955
A40: Less: Net Debt | E40: ='04-BS'!D32-'04-BS'!D6 -> 497
A41: Equity Value | E41: =E39-E40 -> 72796.955
A42: Shares outstanding (mm) | E42: 1530
A43: Implied Share Price | E43: =E41/E42 -> 47.579709

Sheet 07-WACC
A1: NIKE INC — WACC
A2: Source / Justification
A4: MARKET INPUTS
A5: Risk-free rate (Rf) | B5: 0.044 | C5: 10-year US Treasury yield — Jun 2026
A6: Equity Risk Premium (ERP) | B6: 0.055 | C6: Long-run historical premium (assumption). Damodaran implied ERP: 4.23% (Jan 2026), 4.20% mature market (Jul 2026)
A7: Beta (β) | B7: 1.32 | C7: Yahoo Finance 5Y monthly — June 2026
A9: COST OF EQUITY (CAPM)
A10: Ke | B10: =B5+B7*B6 -> 0.1166 | C10: Rf + β * ERP
A12: COST OF DEBT
A13: Pre-tax cost of debt (Kd) | B13: 0.036 | C13: Nike avg coupon rate — 10-K FY2025 Note 7
A14: Tax rate | B14: ='01-Assumption'!E18 -> 0.185 | C14: Lien vers 01-Assumption — 18.5%
A15: Kd after-tax | B15: =B13*(1-B14) -> 0.02934 | C15: Kd × (1 − Tax rate)
A17: CAPITAL STRUCTURE
A18: Market capitalization ($mm) | B18: 68850 | C18: Nike market cap — June 2026 (~$45/share × 1,530mm shares)
A19: Long-term debt ($mm) | B19: ='04-BS'!D32 -> 7961 | C19: Lien vers 04-BS — LT Debt FY2025 = $7,961mm
A20: Total capital V ($mm) | B20: =B18+B19 -> 76811 | C20: Market cap + LT Debt
A21: E/V (equity weight) | B21: =B18/B20 -> 0.89635599 | C21: Market cap / V
A22: D/V (debt weight) | B22: =B19/B20 -> 0.10364401 | C22: LT Debt / V
A24: WACC
A25: WACC | B25: =B10*B21+B15*B22 -> 0.10755602 | C25: Ke × E/V + Kd(1−t) × D/V

Sheet 08-ASSUM
A1: NIKE INC — MODEL ASSUMPTIONS
A3: Assumption | B3: Value | C3: Justification
A4: REVENUE
A5: Revenue growth FY2026E | B5: ='01-Assumption'!E5 -> 0.05 | C5: Analyst consensus FY2025 earnings call — recovery from -9.8% FY2025 decline
A6: Revenue growth FY2027E | B6: ='01-Assumption'!F5 -> 0.07 | C6: Continued recovery — EMEA +8%, Greater China +8%, APLA +9%
A8: MARGINS
A9: Gross Margin FY2026E | B9: ='01-Assumption'!E14 -> 0.445 | C9: Recovery toward 44-46% historical range — DTC mix shift and input cost normalization
A10: Gross Margin FY2027E | B10: ='01-Assumption'!F14 -> 0.45 | C10: Continued DTC expansion — management targets 45%+ medium term
A11: EBIT margin FY2028-2030E | B11: 13.5% / 14.0% / 14.0% | C11: Operating leverage from Win Now cost program — $2bn savings target
A12: Effective Tax Rate | B12: ='01-Assumption'!E18 -> 0.185 | C12: Consistent with Nike 3-year historical average per 10-K income tax note
A14: CASH FLOW
A15: D&A % of Revenue | B15: ='01-Assumption'!E21 -> 0.032 | C15: Normalization assumption — above FY2023-25 actual avg (~1.5%). Reflects expected capex recovery
A16: Capex % of Revenue | B16: ='01-Assumption'!E22 -> 0.035 | C16: Normalization assumption — above FY2023-25 actual avg (~1.5%). Management guidance for capex recovery
A17: NWC % of Revenue | B17: 0.18 | C17: 18% simplifying assumption (FY2025 actual: 27.6%). At 27.6%, base case ≈ $43
A19: WACC
A20: Risk-free rate (Rf) | B20: ='07-WACC'!B5 -> 0.044 | C20: 10-year US Treasury yield — June 2026
A21: Equity Risk Premium (ERP) | B21: ='07-WACC'!B6 -> 0.055 | C21: Long-run historical premium (assumption). Damodaran implied ERP: 4.23% (Jan 2026), 4.20% mature market (Jul 2026)
A22: Beta (β) | B22: ='07-WACC'!B7 -> 1.32 | C22: Yahoo Finance 5Y monthly — June 2026 (updated from 0.83 used in initial model)
A23: WACC | B23: ='07-WACC'!B25 -> 0.10755602 | C23: Ke × E/V + Kd(1-t) × D/V — Nike equity-heavy structure 89% E/V
A25: TERMINAL VALUE
A26: Terminal growth rate (g) | B26: ='06-DCF'!E33 -> 0.025 | C26: 2.5% — consistent with long-term US GDP growth and Nike brand durability
A27: Terminal Value | B27: ='06-DCF'!E34 -> 80886.623 | C27: Gordon Growth Model — TV represents 66.2% of total EV (updated with β 1.32)
A29: PRICE TARGET
A30: Implied Share Price | B30: ='06-DCF'!E43 -> 47.579709 | C30: Base case DCF — WACC 10.76%, g 2.5%
A31: Current Price (Jun 2026) | B31: 45 | C31: Yahoo Finance — June 2026 approximate (~$45/share)
A32: Upside / (Downside) | B32: =(B30-B31)/B31 -> 0.057326869 | C32: Base case implies +5.7% upside vs current market price ($45)

Sheet 09-SENS
A1: NIKE INC — SENSITIVITY ANALYSIS
A3: SCENARIO ANALYSIS — Implied Share Price
A5: Scenario | B5: WACC | C5: Terminal growth (g) | D5: Implied Share Price | E5: vs Current Price ($45) | F5: Recommendation
A6: Bear Case | B6: 0.1176 | C6: 0.015 | D6: =(SUMPRODUCT('06-DCF'!E22:I22,1/(1+B6)^{1,2,3,4,5})+('06-DCF'!I22*(1+C6)/(B6-C6))*(1/(1+B6)^5)-'06-DCF'!E40)/'06-DCF'!E42 -> 39.640188 | E6: =D6/45-1 -> -0.11910694 | F6: Sell
A7: Base Case | B7: ='07-WACC'!B25 -> 0.10755602 | C7: 0.025 | D7: =(SUMPRODUCT('06-DCF'!E22:I22,1/(1+B7)^{1,2,3,4,5})+('06-DCF'!I22*(1+C7)/(B7-C7))*(1/(1+B7)^5)-'06-DCF'!E40)/'06-DCF'!E42 -> 47.579709 | E7: =D7/45-1 -> 0.057326869 | F7: Hold
A8: Bull Case | B8: 0.0976 | C8: 0.035 | D8: =(SUMPRODUCT('06-DCF'!E22:I22,1/(1+B8)^{1,2,3,4,5})+('06-DCF'!I22*(1+C8)/(B8-C8))*(1/(1+B8)^5)-'06-DCF'!E40)/'06-DCF'!E42 -> 60.441082 | E8: =D8/45-1 -> 0.34313516 | F8: Buy
